Workbook
Name grain18: '[1]Daily grain data'!#REF!
Name grains: '[1]Daily grain data'!#REF!
Name week4: '[1]Daily grain data'!#REF!
Name Week50s: [1]summary!#REF!
Name Week51s: [1]summary!#REF!
Name Week52s: [1]summary!#REF!

Sheet Definitions
B1: All price data is provided by John Jordan's Farm Market News Service
B2: John Jordan collects daily price information directly from those that producers would sell their production (elevators and processors)
B3: These corn prices represent the average price in the Chatham Kent area, representing a small geographic portion of Ontario, prices will vary across the province
B6: Price Term | C6: Definition
B7: Ontario Large and medium Frame Fed Steers over 1250 lbs.
B8: Ontario Large and medium Frame Fed Heifers over 1000 lbs.
B9: Average of All Stocker Cattle
B10: CME futures live cattle | C10: Reflects contracts exchanging hands on the commodity exchange at Chicago Board of Trade. Prices are calculated for the closest trading contract period in one years time (reflecting crops that have not been harvested) in American Dollars
B11: CME futures Feeder cattle | C11: Reflects contracts exchanging hands on the commodity exchange at Chicago Board of Trade. Prices are calculated for the closest trading contract period in one years time (reflecting crops that have not been harvested) in American Dollars
B12: Canadian Dollar Value | C12: The value of Canadian dollar in valued in American dollars

Sheet CttlePrices_Basis
A1: Ontario Large and Medium Frame Feeder & Fed Cattle and Basis
A2: *Definitions provided on Next sheet
C3: Ontario Large and medium Frame Fed Steers over 1250 lbs. | D3: Ontario Large and medium Frame Fed Heifers over 1000 lbs. | E3: Weighted Average Stocker Steer and Heifer Cattle Price | F3: CME futures live cattle | G3: CME futures Feeder cattle | H3: Canadian Dollar Value (C$/US$) | I3: Steers 500-599 | J3: Steers 900-999 | K3: Fed Steer Rail Price - Low | L3: Fed Steer Rail Price - High | M3: Fed Steer Rail Price - Average | N3: CANFAX Reported Fed Steer Price | O3: Basis for Steers 500-599 (Ont Live minus CME feeder futures) | P3: Basis for Steers 900-999 (Ont Live minus CME feeder futures) | Q3: Basis for Steers (Ont Ave Rail St minus CME live cattle futures)
A4: Year | B4: Week # | C4: $/cwt (live weight) | D4: $/cwt (live weight) | E4: $/cwt (live weight) | F4: US$/cwt | G4: US$/cwt | I4: $/cwt (live weight) | J4: $/cwt (live weight) | K4: ($/CWT carcsas weight) | L4: ($/CWT carcsas weight) | M4: ($/CWT carcsas weight) | N4: CANFAX $/cwt live weight | O4: $/cwt (live weight) | P4: $/cwt (live weight) | Q4: $/cwt (live weight)
A5: 2005 | B5: 1 | C5: 87.92 | D5: 86.75 | E5: 93.976029 | F5: 87.75 | G5: 98.8 | H5: 0.8166732 | I5: 108.72545 | J5: 87.4 | K5: 145 | L5: 150 | M5: 147.5 | O5: =+(I5-(G5/H5)) -> -12.253169 | P5: =+(J5-(G5/H5)) -> -33.578624 | Q5: =+((M5*0.6)-(F5/H5)) -> -18.94812
A6: 2005 | B6: 2 | C6: 86.57 | D6: 85.68 | E6: 96.301999 | F6: 89.15 | G6: 102.15 | H6: 0.82584567 | I6: 112.28545 | J6: 99.58 | K6: 150 | L6: 155 | M6: 152.5 | O6: =+(I6-(G6/H6)) -> -11.405937 | P6: =+(J6-(G6/H6)) -> -24.111392 | Q6: =+((M6*0.6)-(F6/H6)) -> -16.449952
A7: 2005 | B7: 3 | C7: 88.5 | D7: 84.68 | E7: 99.124477 | F7: 89.15 | G7: 102.15 | H7: 0.81698011 | I7: 118.34545 | J7: 101.64 | K7: 147 | L7: 149 | M7: 148 | O7: =+(I7-(G7/H7)) -> -6.6881885 | P7: =+(J7-(G7/H7)) -> -23.393643 | Q7: =+((M7*0.6)-(F7/H7)) -> -20.321383
A8: 2005 | B8: 4 | C8: 89.12 | D8: 86.16 | E8: 103.31212 | F8: 87.9 | G8: 101.25 | H8: 0.80987398 | I8: 122.00545 | J8: 103.6 | K8: 153 | L8: 156 | M8: 154.5 | O8: =+(I8-(G8/H8)) -> -3.0139955 | P8: =+(J8-(G8/H8)) -> -21.41945 | Q8: =+((M8*0.6)-(F8/H8)) -> -15.835404
A9: 2005 | B9: 5 | C9: 88.06 | D9: 85.77 | E9: 103.76846 | F9: 87.67 | G9: 100.22 | H9: 0.80504927 | I9: 125.07545 | J9: 100.69 | M9: 0 | O9: =+(I9-(G9/H9)) -> 0.58617935 | P9: =+(J9-(G9/H9)) -> -23.799275 | Q9: =+((M9*0.6)-(F9/H9)) -> -108.90017
A10: 2005 | B10: 6 | C10: 88.53 | D10: 87.68 | E10: 105.76948 | F10: 86.82 | G10: 99.35 | H10: 0.8020018 | I10: 125.23545 | J10: 105.63 | K10: 151 | L10: 155 | M10: 153 | O10: =+(I10-(G10/H10)) -> 1.3579265 | P10: =+(J10-(G10/H10)) -> -18.247528 | Q10: =+((M10*0.6)-(F10/H10)) -> -16.454122
A11: 2005 | B11: 7 | C11: 93.93 | D11: 91.7 | E11: 109.57123 | F11: 85.45 | G11: 98.3 | H11: 0.81032024 | I11: 128.78545 | J11: 100.37 | K11: 158 | L11: 160 | M11: 159 | O11: =+(I11-(G11/H11)) -> 7.4753905 | P11: =+(J11-(G11/H11)) -> -20.940064 | Q11: =+((M11*0.6)-(F11/H11)) -> -10.052136
A12: 2005 | B12: 8 | C12: 93.31 | D12: 91.81 | E12: 106.33177 | F12: 85.45 | G12: 97.85 | H12: 0.80848587 | I12: 127.94545 | J12: 103.82 | K12: 160 | L12: 162 | M12: 161 | O12: =+(I12-(G12/H12)) -> 6.9167465 | P12: =+(J12-(G12/H12)) -> -17.208708 | Q12: =+((M12*0.6)-(F12/H12)) -> -9.091396
A13: 2005 | B13: 9 | C13: 92.43 | D13: 91.84 | E13: 104.18292 | F13: 89.02 | G13: 102.67 | H13: 0.80733708 | I13: 123.44545 | J13: 99.34 | K13: 158 | L13: 160 | M13: 159 | O13: =+(I13-(G13/H13)) -> -3.7257143 | P13: =+(J13-(G13/H13)) -> -27.831169 | Q13: =+((M13*0.6)-(F13/H13)) -> -14.863733
A14: 2005 | B14: 10 | C14: 85.37 | D14: 82.76 | E14: 95.956875 | F14: 89.1 | G14: 104.9 | H14: 0.82487833 | I14: 113.03545 | J14: 94.06 | K14: 148 | L14: 149 | M14: 148.5 | O14: =+(I14-(G14/H14)) -> -14.134815 | P14: =+(J14-(G14/H14)) -> -33.11027 | Q14: =+((M14*0.6)-(F14/H14)) -> -18.91593
A15: 2005 | B15: 11 | C15: 79.5 | D15: 77.69 | E15: 92.070144 | F15: 87.4 | G15: 105.62 | H15: 0.8297378 | I15: 112.11545 | J15: 89.06 | K15: 138 | L15: 145 | M15: 141.5 | O15: =+(I15-(G15/H15)) -> -15.177769 | P15: =+(J15-(G15/H15)) -> -38.233224 | Q15: =+((M15*0.6)-(F15/H15)) -> -20.43448
A16: 2005 | B16: 12 | C16: 83.91 | D16: 79.41 | E16: 95.375077 | F16: 88.35 | G16: 104.92 | H16: 0.82601962 | I16: 115.23545 | J16: 94.77 | K16: 138 | L16: 145 | M16: 141.5 | O16: =+(I16-(G16/H16)) -> -11.78332 | P16: =+(J16-(G16/H16)) -> -32.248775 | Q16: =+((M16*0.6)-(F16/H16)) -> -22.058719
A17: 2005 | B17: 13 | C17: 90.1 | D17: 87.31 | E17: 97.614477 | G17: 104.92 | H17: 0.82263903 | I17: 116.94545 | J17: 96.94 | K17: 149 | L17: 153 | M17: 151 | O17: =+(I17-(G17/H17)) -> -10.595297 | P17: =+(J17-(G17/H17)) -> -30.600752 | Q17: =+((M17*0.6)-(F17/H17)) -> 90.6
A18: 2005 | B18: 14 | C18: 88.78 | D18: 86.26 | E18: 100.13414 | F18: 88.27 | G18: 108.42 | H18: 0.81863877 | I18: 123.62545 | J18: 94.83 | K18: 152 | L18: 154 | M18: 153 | O18: =+(I18-(G18/H18)) -> -8.8139123 | P18: =+(J18-(G18/H18)) -> -37.609367 | Q18: =+((M18*0.6)-(F18/H18)) -> -16.025336
A19: 2005 | B19: 15 | C19: 83.61 | D19: 79.92 | E19: 100.34428 | F19: 84.42 | G19: 106.22 | H19: 0.80721977 | I19: 120.15545 | J19: 93.35 | K19: 142 | L19: 150 | M19: 146 | O19: =+(I19-(G19/H19)) -> -11.432006 | P19: =+(J19-(G19/H19)) -> -38.23746 | Q19: =+((M19*0.6)-(F19/H19)) -> -16.981184
A20: 2005 | B20: 16 | C20: 85.22 | D20: 77.77 | E20: 95.200881 | F20: 85.72 | G20: 106.9 | H20: 0.80623055 | I20: 115.07545 | J20: 92.7 | K20: 142 | L20: 144 | M20: 143 | O20: =+(I20-(G20/H20)) -> -17.516891 | P20: =+(J20-(G20/H20)) -> -39.892346 | Q20: =+((M20*0.6)-(F20/H20)) -> -20.521945
A21: 2005 | B21: 17 | C21: 88.53 | D21: 84.12 | E21: 96.933608 | F21: 85.62 | G21: 108.67 | H21: 0.80151326 | I21: 114.53545 | J21: 90.34 | M21: 0 | O21: =+(I21-(G21/H21)) -> -21.045584 | P21: =+(J21-(G21/H21)) -> -45.241039 | Q21: =+((M21*0.6)-(F21/H21)) -> -106.82294
A22: 2005 | B22: 18 | C22: 87.59 | D22: 84.88 | E22: 98.873049 | F22: 85.05 | G22: 109.55 | H22: 0.80014082 | I22: 115.45545 | J22: 92.91 | K22: 149 | L22: 152 | M22: 150.5 | O22: =+(I22-(G22/H22)) -> -21.457944 | P22: =+(J22-(G22/H22)) -> -44.003399 | Q22: =+((M22*0.6)-(F22/H22)) -> -15.993789
A23: 2005 | B23: 19 | C23: 88.2 | D23: 84.8 | E23: 100.36032 | F23: 86.57 | G23: 112.32 | H23: 0.80201466 | I23: 116.58545 | J23: 91.25 | K23: 148 | L23: 151 | M23: 149.5 | O23: =+(I23-(G23/H23)) -> -23.461861 | P23: =+(J23-(G23/H23)) -> -48.797315 | Q23: =+((M23*0.6)-(F23/H23)) -> -18.24067
A24: 2005 | B24: 20 | C24: 85.62 | D24: 84.05 | E24: 99.973779 | F24: 85.62 | G24: 111.55 | H24: 0.79062633 | I24: 116.59545 | J24: 95.77 | M24: 0 | O24: =+(I24-(G24/H24)) -> -24.495216 | P24: =+(J24-(G24/H24)) -> -45.320671 | Q24: =+((M24*0.6)-(F24/H24)) -> -108.29389
A25: 2005 | B25: 21 | C25: 85.21 | D25: 82.03 | E25: 98.435689 | F25: 84.07 | G25: 111.45 | H25: 0.79180325 | I25: 117.95545 | J25: 97.06 | K25: 146 | L25: 148 | M25: 147 | O25: =+(I25-(G25/H25)) -> -22.799208 | P25: =+(J25-(G25/H25)) -> -43.694663 | Q25: =+((M25*0.6)-(F25/H25)) -> -17.975366
A26: 2005 | B26: 22 | C26: 86.9 | D26: 81.09 | E26: 98.155457 | F26: 83.42 | G26: 111.7 | H26: 0.7999872 | I26: 118.00545 | J26: 95.14 | K26: 145 | L26: 147 | M26: 146 | O26: =+(I26-(G26/H26)) -> -21.621779 | P26: =+(J26-(G26/H26)) -> -44.487234 | Q26: =+((M26*0.6)-(F26/H26)) -> -16.676668
A27: 2005 | B27: 23 | C27: 87.34 | D27: 83.72 | E27: 98.472063 | F27: 82.12 | G27: 111.25 | H27: 0.80124353 | I27: 118.52545 | J27: 96.96 | M27: 0 | O27: =+(I27-(G27/H27)) -> -20.32122 | P27: =+(J27-(G27/H27)) -> -41.886675 | Q27: =+((M27*0.6)-(F27/H27)) -> -102.49069
A28: 2005 | B28: 24 | C28: 86.25 | D28: 83.58 | E28: 95.465468 | F28: 79.9 | G28: 107.57 | H28: 0.80278728 | I28: 110.22545 | J28: 94.2 | K28: 147 | L28: 150 | M28: 148.5 | O28: =+(I28-(G28/H28)) -> -23.770192 | P28: =+(J28-(G28/H28)) -> -39.795646 | Q28: =+((M28*0.6)-(F28/H28)) -> -10.428234
A29: 2005 | B29: 25 | C29: 86.97 | D29: 82.7 | E29: 97.777246 | F29: 79.87 | G29: 108.45 | H29: 0.81142486 | I29: 108.04545 | J29: 98.49 | K29: 146 | L29: 148 | M29: 147 | O29: =+(I29-(G29/H29)) -> -25.608325 | P29: =+(J29-(G29/H29)) -> -35.16378 | Q29: =+((M29*0.6)-(F29/H29)) -> -10.231788
A30: 2005 | B30: 26 | C30: 89.19 | D30: 85.62 | E30: 94.72758 | F30: 79.3 | G30: 109.42 | H30: 0.81439857 | I30: 110.63545 | J30: 96.92 | M30: 0 | O30: =+(I30-(G30/H30)) -> -23.721363 | P30: =+(J30-(G30/H30)) -> -37.436818 | Q30: =+((M30*0.6)-(F30/H30)) -> -97.37247
A31: 2005 | B31: 27 | C31: 90.28 | D31: 88.44 | E31: 97.85347 | F31: 79.35 | G31: 111.97 | H31: 0.81050413 | I31: 114.11545 | J31: 99.48 | K31: 149 | L31: 158 | M31: 153.5 | O31: =+(I31-(G31/H31)) -> -24.033131 | P31: =+(J31-(G31/H31)) -> -38.668586 | Q31: =+((M31*0.6)-(F31/H31)) -> -5.80203
A32: 2005 | B32: 28 | C32: 93 | D32: 90.06 | E32: 101.18911 | F32: 78.52 | G32: 106.15 | H32: 0.82622777 | I32: 115.98545 | J32: 100.33 | K32: 157 | L32: 159 | M32: 158 | O32: =+(I32-(G32/H32)) -> -12.490013 | P32: =+(J32-(G32/H32)) -> -28.145468 | Q32: =+((M32*0.6)-(F32/H32)) -> -0.2343264
A33: 2005 | B33: 29 | C33: 95.28 | D33: 92.36 | E33: 103.77208 | F33: 79.25 | G33: 107.65 | H33: 0.82081589 | I33: 123.51545 | J33: 102.3 | K33: 160 | L33: 163 | M33: 161.5 | O33: =+(I33-(G33/H33)) -> -7.6345405 | P33: =+(J33-(G33/H33)) -> -28.849995 | Q33: =+((M33*0.6)-(F33/H33)) -> 0.349725
A34: 2005 | B34: 30 | C34: 91.51 | D34: 87.07 | E34: 104.6531 | F34: 80.57 | G34: 110.4 | H34: 0.81396106 | I34: 120.17545 | J34: 105.51 | K34: 157 | L34: 161 | M34: 159 | O34: =+(I34-(G34/H34)) -> -15.457569 | P34: =+(J34-(G34/H34)) -> -30.123024 | Q34: =+((M34*0.6)-(F34/H34)) -> -3.5850792
A35: 2005 | B35: 31 | C35: 92.35 | D35: 89.95 | E35: 106.28771 | F35: 81.92 | G35: 108.57 | H35: 0.82209799 | I35: 120.42545 | J35: 106.12 | K35: 155 | L35: 162 | M35: 158.5 | O35: =+(I35-(G35/H35)) -> -11.639093 | P35: =+(J35-(G35/H35)) -> -25.944548 | Q35: =+((M35*0.6)-(F35/H35)) -> -4.547488
A36: 2005 | B36: 32 | C36: 94.33 | D36: 90.14 | E36: 108.23654 | F36: 80.07 | G36: 106.62 | H36: 0.82833571 | I36: 125.50545 | J36: 104.06 | K36: 159 | L36: 163 | M36: 161 | O36: =+(I36-(G36/H36)) -> -3.2104743 | P36: =+(J36-(G36/H36)) -> -24.655929 | Q36: =+((M36*0.6)-(F36/H36)) -> -0.0637068
A37: 2005 | B37: 33 | C37: 92.42 | D37: 87.1 | E37: 110.30621 | F37: 82.1 | G37: 108.97 | H37: 0.8285416 | I37: 125.92545 | J37: 106.35 | K37: 158 | L37: 160 | M37: 159 | O37: =+(I37-(G37/H37)) -> -5.5947973 | P37: =+(J37-(G37/H37)) -> -25.170252 | Q37: =+((M37*0.6)-(F37/H37)) -> -3.689774
A38: 2005 | B38: 34 | C38: 90.88 | D38: 84.8 | E38: 109.38054 | F38: 83.05 | G38: 109.87 | H38: 0.83557546 | I38: 123.70545 | J38: 106.5 | K38: 156 | L38: 158 | M38: 157 | O38: =+(I38-(G38/H38)) -> -7.7847641 | P38: =+(J38-(G38/H38)) -> -24.990219 | Q38: =+((M38*0.6)-(F38/H38)) -> -5.192579
A39: 2005 | B39: 35 | C39: 90.96 | D39: 88.18 | E39: 112.55559 | F39: 81.2 | G39: 108.57 | H39: 0.84013845 | I39: 123.43545 | J39: 109.95 | K39: 158 | L39: 160 | M39: 159 | O39: =+(I39-(G39/H39)) -> -5.7932451 | P39: =+(J39-(G39/H39)) -> -19.2787 | Q39: =+((M39*0.6)-(F39/H39)) -> -1.250736
A40: 2005 | B40: 36 | C40: 91.3 | D40: 88.83 | E40: 112.57565 | F40: 87.8 | G40: 113.17 | H40: 0.84534427 | I40: 127.59545 | J40: 108.11 | M40: 0 | O40: =+(I40-(G40/H40)) -> -6.278997 | P40: =+(J40-(G40/H40)) -> -25.764451 | Q40: =+((M40*0.6)-(F40/H40)) -> -103.86301
...

Sheet Steer price comp
D1: Comparison of Fed Steer Carcass Weight Price Options
D2: CANFAX Reported Fed Steer Price - farmers report price based on carcass weight and CANFAX converts to liveweight including a transport cost to packer | G2: BFO Reported Average | H2: Comparison | K2: Ontario Auction Large and medium Frame Fed Steers over 1250 lb | L2: CANFAX Reported Fed Steer Price -plus transport cost
C3: - | D3: CANFAX $/cwt live weight | E3: Transport Cost $/cwt carcass weight | F3: CANFAX $/cwt Carcass Weight adjusted for transport cost | G3: BFO $/cwt Average Fed Steer Carcass Weight | H3: Weekly Difference in Carcass Weight Price Options - $/cwt Carcass Weight | I3: Average Difference since Jan 2020 | K3: Ontario Auction $/cwt liveweight | L3: CANFAX - plus transport cost $/cwt liveweight | M3: Weekly Difference between CANFAX Liveweight Fed Steer Price (plus transport cost) and Ontario Auction Fed Steer Price | N3: Average Difference since Jan 2020
A4: 2020 | B4: 1 | C4: =CONCATENATE(A4,$C$3,B4) -> 2020-1 | D4: 148.46 | E4: 2 | F4: =D4/0.6+2 -> 249.43333 | G4: 247 | H4: =F4-G4 -> 2.4333333 | I4: =AVERAGE(H4:H211) -> 1.5052764 | K4: 137.13 | L4: =F4*0.6 -> 149.66 | M4: 12.53 | N4: =AVERAGE(M4:M211) -> 4.7566834
A5: 2020 | B5: 2 | C5: =CONCATENATE(A5,$C$3,B5) -> 2020-2 | D5: 149.1 | E5: 2 | F5: =D5/0.6+2 -> 250.5 | G5: 247.5 | H5: =F5-G5 -> 3 | K5: 139.71 | L5: =F5*0.6 -> 150.3 | M5: =L5-K5 -> 10.59
A6: 2020 | B6: 3 | C6: =CONCATENATE(A6,$C$3,B6) -> 2020-3 | D6: 150.9 | E6: 2 | F6: =D6/0.6+2 -> 253.5 | G6: 252.5 | H6: =F6-G6 -> 1 | K6: 143.12 | L6: =F6*0.6 -> 152.1 | M6: =L6-K6 -> 8.98
A7: 2020 | B7: 4 | C7: =CONCATENATE(A7,$C$3,B7) -> 2020-4 | D7: 151.99 | E7: 2 | F7: =D7/0.6+2 -> 255.31667 | G7: 252.5 | H7: =F7-G7 -> 2.8166667 | K7: 143.82 | L7: =F7*0.6 -> 153.19 | M7: =L7-K7 -> 9.37
A8: 2020 | B8: 5 | C8: =CONCATENATE(A8,$C$3,B8) -> 2020-5 | D8: 152.1 | E8: 2 | F8: =D8/0.6+2 -> 255.5 | G8: 253 | H8: =F8-G8 -> 2.5 | K8: 143.43 | L8: =F8*0.6 -> 153.3 | M8: =L8-K8 -> 9.87
A9: 2020 | B9: 6 | C9: =CONCATENATE(A9,$C$3,B9) -> 2020-6 | D9: 151.95 | E9: 2 | F9: =D9/0.6+2 -> 255.25 | G9: 254.5 | H9: =F9-G9 -> 0.75 | K9: 138.85 | L9: =F9*0.6 -> 153.15 | M9: =L9-K9 -> 14.3
A10: 2020 | B10: 7 | C10: =CONCATENATE(A10,$C$3,B10) -> 2020-7 | D10: 150.86 | E10: 2 | F10: =D10/0.6+2 -> 253.43333 | G10: 253 | H10: =F10-G10 -> 0.43333333 | K10: 138.93 | L10: =F10*0.6 -> 152.06 | M10: =L10-K10 -> 13.13
A11: 2020 | B11: 8 | C11: =CONCATENATE(A11,$C$3,B11) -> 2020-8 | D11: 150.19 | E11: 2 | F11: =D11/0.6+2 -> 252.31667 | G11: 252.5 | H11: =F11-G11 -> -0.18333333 | K11: 139.96 | L11: =F11*0.6 -> 151.39 | M11: =L11-K11 -> 11.43
A12: 2020 | B12: 9 | C12: =CONCATENATE(A12,$C$3,B12) -> 2020-9 | D12: 147.55 | E12: 2 | F12: =D12/0.6+2 -> 247.91667 | G12: 247.5 | H12: =F12-G12 -> 0.41666667 | K12: 143.84 | L12: =F12*0.6 -> 148.75 | M12: =L12-K12 -> 4.91
A13: 2020 | B13: 10 | C13: =CONCATENATE(A13,$C$3,B13) -> 2020-10 | D13: 145.92 | E13: 2 | F13: =D13/0.6+2 -> 245.2 | G13: 245 | H13: =F13-G13 -> 0.2 | K13: 143.58 | L13: =F13*0.6 -> 147.12 | M13: =L13-K13 -> 3.54
A14: 2020 | B14: 11 | C14: =CONCATENATE(A14,$C$3,B14) -> 2020-11 | D14: 145.92 | E14: 2 | F14: =D14/0.6+2 -> 245.2 | G14: 245 | H14: =F14-G14 -> 0.2 | K14: 135.87 | L14: =F14*0.6 -> 147.12 | M14: =L14-K14 -> 11.25
A15: 2020 | B15: 12 | C15: =CONCATENATE(A15,$C$3,B15) -> 2020-12 | D15: 140.1 | E15: 2 | F15: =D15/0.6+2 -> 235.5 | G15: 235 | H15: =F15-G15 -> 0.5 | K15: 135.68 | L15: =F15*0.6 -> 141.3 | M15: =L15-K15 -> 5.62
A16: 2020 | B16: 13 | C16: =CONCATENATE(A16,$C$3,B16) -> 2020-13 | D16: 140.1 | E16: 2 | F16: =D16/0.6+2 -> 235.5 | G16: 235 | H16: =F16-G16 -> 0.5 | K16: 138.46 | L16: =F16*0.6 -> 141.3 | M16: =L16-K16 -> 2.84
... A54: 2020 | B54: 51 | C54: =CONCATENATE(A54,$C$3,B54) -> 2020-51 | D54: 138.3 | E54: 2 | F54: =D54/0.6+2 -> 232.5 | G54: 232 | H54: =F54-G54 -> 0.5 | K54: 115.31 | L54: =F54*0.6 -> 139.5 | M54: =L54-K54 -> 24.19
A55: 2020 | B55: 52 | C55: =CONCATENATE(A55,$C$3,B55) -> 2020-52 | D55: 138.3 | E55: 2 | F55: =D55/0.6+2 -> 232.5 | G55: 232 | H55: =F55-G55 -> 0.5 | K55: =+K54 -> 115.31 | L55: =F55*0.6 -> 139.5 | M55: =+M54 -> 24.19
A56: 2021 | B56: 1 | C56: =CONCATENATE(A56,$C$3,B56) -> 2021-1 | D56: 139.97 | E56: 2 | F56: =D56/0.6+2 -> 235.28333 | G56: 234 | H56: =F56-G56 -> 1.2833333 | K56: 129.23 | L56: =F56*0.6 -> 141.17 | M56: =L56-K56 -> 11.94
A57: 2021 | B57: 2 | C57: =CONCATENATE(A57,$C$3,B57) -> 2021-2 | D57: 140.7 | E57: 2 | F57: =D57/0.6+2 -> 236.5 | G57: 236 | H57: =F57-G57 -> 0.5 | K57: 129.98 | L57: =F57*0.6 -> 141.9 | M57: =L57-K57 -> 11.92
A58: 2021 | B58: 3 | C58: =CONCATENATE(A58,$C$3,B58) -> 2021-3 | D58: 140.92 | E58: 2 | F58: =D58/0.6+2 -> 236.86667 | G58: 236 | H58: =F58-G58 -> 0.86666667 | K58: 133.5 | L58: =F58*0.6 -> 142.12 | M58: =L58-K58 -> 8.62
A59: 2021 | B59: 4 | C59: =CONCATENATE(A59,$C$3,B59) -> 2021-4 | D59: 140.7 | E59: 2 | F59: =D59/0.6+2 -> 236.5 | G59: 236 | H59: =F59-G59 -> 0.5 | K59: 134.16 | L59: =F59*0.6 -> 141.9 | M59: =L59-K59 -> 7.74
A60: 2021 | B60: 5 | C60: =CONCATENATE(A60,$C$3,B60) -> 2021-5 | D60: 140.84 | E60: 2 | F60: =D60/0.6+2 -> 236.73333 | G60: 237 | H60: =F60-G60 -> -0.26666667 | K60: 138.07 | L60: =F60*0.6 -> 142.04 | M60: =L60-K60 -> 3.97
A61: 2021 | B61: 6 | C61: =CONCATENATE(A61,$C$3,B61) -> 2021-6 | D61: 143.1 | E61: 2 | F61: =D61/0.6+2 -> 240.5 | G61: 240 | H61: =F61-G61 -> 0.5 | K61: 135.93 | L61: =F61*0.6 -> 144.3 | M61: =L61-K61 -> 8.37
A62: 2021 | B62: 7 | C62: =CONCATENATE(A62,$C$3,B62) -> 2021-7 | D62: 143.14 | E62: 2 | F62: =D62/0.6+2 -> 240.56667 | G62: 240.5 | H62: =F62-G62 -> 0.066666667 | K62: 131.7 | L62: =F62*0.6 -> 144.34 | M62: =L62-K62 -> 12.64
A63: 2021 | B63: 8 | C63: =CONCATENATE(A63,$C$3,B63) -> 2021-8 | D63: 144.17 | E63: 2 | F63: =D63/0.6+2 -> 242.28333 | G63: 241 | H63: =F63-G63 -> 1.2833333 | K63: 136.79 | L63: =F63*0.6 -> 145.37 | M63: =L63-K63 -> 8.58
A64: 2021 | B64: 9 | C64: =CONCATENATE(A64,$C$3,B64) -> 2021-9 | D64: 144.16 | E64: 2 | F64: =D64/0.6+2 -> 242.26667 | G64: 241 | H64: =F64-G64 -> 1.2666667 | K64: 140.1 | L64: =F64*0.6 -> 145.36 | M64: =L64-K64 -> 5.26
A65: 2021 | B65: 10 | C65: =CONCATENATE(A65,$C$3,B65) -> 2021-10 | D65: 143.49 | E65: 2 | F65: =D65/0.6+2 -> 241.15 | G65: 241.5 | H65: =F65-G65 -> -0.35 | K65: 141.07 | L65: =F65*0.6 -> 144.69 | M65: =L65-K65 -> 3.62
A66: 2021 | B66: 11 | C66: =CONCATENATE(A66,$C$3,B66) -> 2021-11 | D66: 143.46 | E66: 2 | F66: =D66/0.6+2 -> 241.1 | G66: 241.5 | H66: =F66-G66 -> -0.4 | K66: 140.79 | L66: =F66*0.6 -> 144.66 | M66: =L66-K66 -> 3.87
A67: 2021 | B67: 12 | C67: =CONCATENATE(A67,$C$3,B67) -> 2021-12 | D67: 143.1 | E67: 2 | F67: =D67/0.6+2 -> 240.5 | G67: 240 | H67: =F67-G67 -> 0.5 | K67: 140.3 | L67: =F67*0.6 -> 144.3 | M67: =L67-K67 -> 4
... A107: 2021 | B107: 52 | C107: =CONCATENATE(A107,$C$3,B107) -> 2021-52 | D107: 173.05 | E107: 2 | F107: =D107/0.6+2 -> 290.41667 | G107: 276 | H107: =F107-G107 -> 14.416667 | K107: 167.13 | L107: =F107*0.6 -> 174.25 | M107: =L107-K107 -> 7.12
A108: 2022 | B108: 1 | C108: =CONCATENATE(A108,$C$3,B108) -> 2022-1 | D108: =+_xlfn.IFNA('[2]weekly-canfax-data'!AM8,"") -> 173.4 | E108: 2 | F108: =D108/0.6+2 -> 291 | G108: =+CttlePrices_Basis!M889 -> 291.5 | H108: =IFERROR(F108-G108,"") -> -0.5 | K108: =+_xlfn.IFNA(CttlePrices_Basis!C889,"") -> 171.37 | L108: =IFERROR(F108*0.6,"") -> 174.6 | M108: =IFERROR(L108-K108,"") -> 3.23
A109: 2022 | B109: 2 | C109: =CONCATENATE(A109,$C$3,B109) -> 2022-2 | D109: =+_xlfn.IFNA('[2]weekly-canfax-data'!AM9,"") -> 173.04 | E109: 2 | F109: =D109/0.6+2 -> 290.4 | G109: =CttlePrices_Basis!M890 -> 290 | H109: =IFERROR(F109-G109,"") -> 0.4 | K109: =+_xlfn.IFNA(CttlePrices_Basis!C890,"") -> 169.2 | L109: =IFERROR(F109*0.6,"") -> 174.24 | M109: =IFERROR(L109-K109,"") -> 5.04
A110: 2022 | B110: 3 | C110: =CONCATENATE(A110,$C$3,B110) -> 2022-3 | D110: =+_xlfn.IFNA('[2]weekly-canfax-data'!AM10,"") -> 173.1 | E110: 2 | F110: =D110/0.6+2 -> 290.5 | G110: =CttlePrices_Basis!M891 -> 290 | H110: =IFERROR(F110-G110,"") -> 0.5 | K110: =+_xlfn.IFNA(CttlePrices_Basis!C891,"") -> 169.71 | L110: =IFERROR(F110*0.6,"") -> 174.3 | M110: =IFERROR(L110-K110,"") -> 4.59
A111: 2022 | B111: 4 | C111: =CONCATENATE(A111,$C$3,B111) -> 2022-4 | D111: =+_xlfn.IFNA('[2]weekly-canfax-data'!AM11,"") -> 173.1 | E111: 2 | F111: =D111/0.6+2 -> 290.5 | G111: =CttlePrices_Basis!M892 -> 290 | H111: =IFERROR(F111-G111,"") -> 0.5 | K111: =+_xlfn.IFNA(CttlePrices_Basis!C892,"") -> 166.91 | L111: =IFERROR(F111*0.6,"") -> 174.3 | M111: =IFERROR(L111-K111,"") -> 7.39
A112: 2022 | B112: 5 | C112: =CONCATENATE(A112,$C$3,B112) -> 2022-5 | D112: =+_xlfn.IFNA('[2]weekly-canfax-data'!AM12,"") -> 173.1 | E112: 2 | F112: =D112/0.6+2 -> 290.5 | G112: =CttlePrices_Basis!M893 -> 290 | H112: =IFERROR(F112-G112,"") -> 0.5 | K112: =+_xlfn.IFNA(CttlePrices_Basis!C893,"") -> 171.93 | L112: =IFERROR(F112*0.6,"") -> 174.3 | M112: =IFERROR(L112-K112,"") -> 2.37
A113: 2022 | B113: 6 | C113: =CONCATENATE(A113,$C$3,B113) -> 2022-6 | D113: =+_xlfn.IFNA('[2]weekly-canfax-data'!AM13,"") -> 173.1 | E113: 2 | F113: =D113/0.6+2 -> 290.5 | G113: =CttlePrices_Basis!M894 -> 290 | H113: =IFERROR(F113-G113,"") -> 0.5 | K113: =+_xlfn.IFNA(CttlePrices_Basis!C894,"") -> 169.26 | L113: =IFERROR(F113*0.6,"") -> 174.3 | M113: =IFERROR(L113-K113,"") -> 5.04
A114: 2022 | B114: 7 | C114: =CONCATENATE(A114,$C$3,B114) -> 2022-7 | D114: =+_xlfn.IFNA('[2]weekly-canfax-data'!AM14,"") -> 173.1 | E114: 2 | F114: =D114/0.6+2 -> 290.5 | G114: =CttlePrices_Basis!M895 -> 290 | H114: =IFERROR(F114-G114,"") -> 0.5 | K114: =+_xlfn.IFNA(CttlePrices_Basis!C895,"") -> 165.89 | L114: =IFERROR(F114*0.6,"") -> 174.3 | M114: =IFERROR(L114-K114,"") -> 8.41
A115: 2022 | B115: 8 | C115: =CONCATENATE(A115,$C$3,B115) -> 2022-8 | D115: =+_xlfn.IFNA('[2]weekly-canfax-data'!AM15,"") -> 173.1 | E115: 2 | F115: =D115/0.6+2 -> 290.5 | G115: =CttlePrices_Basis!M896 -> 290 | H115: =IFERROR(F115-G115,"") -> 0.5 | K115: =+_xlfn.IFNA(CttlePrices_Basis!C896,"") -> 165.31 | L115: =IFERROR(F115*0.6,"") -> 174.3 | M115: =IFERROR(L115-K115,"") -> 8.99
A116: 2022 | B116: 9 | C116: =CONCATENATE(A116,$C$3,B116) -> 2022-9 | D116: =+_xlfn.IFNA('[2]weekly-canfax-data'!AM16,"") -> 173.1 | E116: 2 | F116: =D116/0.6+2 -> 290.5 | G116: =CttlePrices_Basis!M897 -> 290 | H116: =IFERROR(F116-G116,"") -> 0.5 | K116: =+_xlfn.IFNA(CttlePrices_Basis!C897,"") -> 169.08 | L116: =IFERROR(F116*0.6,"") -> 174.3 | M116: =IFERROR(L116-K116,"") -> 5.22
...

Sheet Market Price
D1: OCA Large & medium frame steers - 900-999 | E1: OCA Large & Medium Farm Steer over 1250+ price
A2: Year | B2: Week | C2: Week Ending | D2: Steer Price $ per cwt | E2: Steer Price $ per cwt
A3: 1999 | B3: 1 | C3: 36168 | D3: 91.56 | E3: 87.94
A4: 1999 | B4: 2 | C4: =C3+7 -> 36175 | D4: 98.4 | E4: 89.38
A5: 1999 | B5: 3 | C5: =C4+7 -> 36182 | D5: 101.88 | E5: 90.68
A6: 1999 | B6: 4 | C6: =C5+7 -> 36189 | D6: 99.18 | E6: 90.32
A7: 1999 | B7: 5 | C7: =C6+7 -> 36196 | D7: 101.97 | E7: 91.1
A8: 1999 | B8: 6 | C8: =C7+7 -> 36203 | D8: 103.57 | E8: 91.19
A9: 1999 | B9: 7 | C9: =C8+7 -> 36210 | D9: 100.32 | E9: 90.62
A10: 1999 | B10: 8 | C10: =C9+7 -> 36217 | D10: 101.27 | E10: 90.86
A11: 1999 | B11: 9 | C11: =C10+7 -> 36224 | D11: 102.58 | E11: 91.89
A12: 1999 | B12: 10 | C12: =C11+7 -> 36231 | D12: 103.58 | E12: 92.68
A13: 1999 | B13: 11 | C13: =C12+7 -> 36238 | D13: 100.99 | E13: 93.34
A14: 1999 | B14: 12 | C14: =C13+7 -> 36245 | D14: 102.19 | E14: 92.54
A15: 1999 | B15: 13 | C15: =C14+7 -> 36252 | D15: 98.8 | E15: 92.58
... A1150: 2020 | B1150: 53 | C1150: =C1149+7 -> 44197 | D1150: 164.98 | E1150: 115.31
A1151: 2021 | B1151: 1 | C1151: =C1150+7 -> 44204 | D1151: =+[1]fedcat!$CS5 -> 176.39 | E1151: =+[1]fedcat!$AB5 -> 129.23
A1152: 2021 | B1152: 2 | C1152: =C1151+7 -> 44211 | D1152: =+[1]fedcat!$CS6 -> 178.45 | E1152: =+[1]fedcat!$AB6 -> 129.98
A1153: 2021 | B1153: 3 | C1153: =C1152+7 -> 44218 | D1153: =+[1]fedcat!$CS7 -> 172.73 | E1153: =+[1]fedcat!$AB7 -> 133.5
A1154: 2021 | B1154: 4 | C1154: =C1153+7 -> 44225 | D1154: =+[1]fedcat!$CS8 -> 175.62 | E1154: =+[1]fedcat!$AB8 -> 134.16
A1155: 2021 | B1155: 5 | C1155: =C1154+7 -> 44232 | D1155: =+[1]fedcat!$CS9 -> 179.09 | E1155: =+[1]fedcat!$AB9 -> 138.07
A1156: 2021 | B1156: 6 | C1156: =C1155+7 -> 44239 | D1156: =+[1]fedcat!$CS10 -> 180.48 | E1156: =+[1]fedcat!$AB10 -> 135.93
A1157: 2021 | B1157: 7 | C1157: =C1156+7 -> 44246 | D1157: =+[1]fedcat!$CS11 -> 181.67 | E1157: =+[1]fedcat!$AB11 -> 131.7
A1158: 2021 | B1158: 8 | C1158: =C1157+7 -> 44253 | D1158: =+[1]fedcat!$CS12 -> 174.87 | E1158: =+[1]fedcat!$AB12 -> 136.79
A1159: 2021 | B1159: 9 | C1159: =C1158+7 -> 44260 | D1159: =+[1]fedcat!$CS13 -> 172.84 | E1159: =+[1]fedcat!$AB13 -> 140.1
A1160: 2021 | B1160: 10 | C1160: =C1159+7 -> 44267 | D1160: =+[1]fedcat!$CS14 -> 172.62 | E1160: =+[1]fedcat!$AB14 -> 141.07
A1161: 2021 | B1161: 11 | C1161: =C1160+7 -> 44274 | D1161: =+[1]fedcat!$CS15 -> 167.37 | E1161: =+[1]fedcat!$AB15 -> 140.79
A1162: 2021 | B1162: 12 | C1162: =C1161+7 -> 44281 | D1162: =+[1]fedcat!$CS16 -> 170.08 | E1162: =+[1]fedcat!$AB16 -> 140.3
... A1168: 2021 | B1168: 18 | C1168: =C1167+7 -> 44323 | D1168: =+[1]fedcat!$CS22 -> 167.62 | E1168: =+[1]fedcat!$AB22 -> 145.72
A1169: 2021 | B1169: 19 | C1169: =C1168+7 -> 44330 | D1169: =+[1]fedcat!$CS$23 -> 166.57 | E1169: =+[1]fedcat!$AB$23 -> 147.25
A1170: 2021 | B1170: 20 | C1170: =C1169+7 -> 44337 | D1170: =+[1]fedcat!$CS24 -> 170.6 | E1170: =+[1]fedcat!$AB24 -> 147.21
A1171: 2021 | B1171: 21 | C1171: =C1170+7 -> 44344 | D1171: =+[1]fedcat!$CS25 -> 171.91 | E1171: =+[1]fedcat!$AB25 -> 151.65
A1172: 2021 | B1172: 22 | C1172: =C1171+7 -> 44351 | D1172: =+[1]fedcat!$CS26 -> 176.78 | E1172: =+[1]fedcat!$AB26 -> 155.18
A1173: 2021 | B1173: 23 | C1173: =C1172+7 -> 44358 | D1173: =+[1]fedcat!$CS27 -> 174.92 | E1173: =+[1]fedcat!$AB27 -> 160.81
A1174: 2021 | B1174: 24 | C1174: =C1173+7 -> 44365 | D1174: =+[1]fedcat!$CS28 -> 177.21 | E1174: =+[1]fedcat!$AB28 -> 158.79
A1175: 2021 | B1175: 25 | C1175: =C1174+7 -> 44372 | D1175: =+[1]fedcat!$CS29 -> 177.25 | E1175: =+[1]fedcat!$AB29 -> 160.48
A1176: 2021 | B1176: 26 | C1176: =C1175+7 -> 44379 | D1176: =+[1]fedcat!$CS30 -> 183.77 | E1176: =+[1]fedcat!$AB30 -> 159.17
A1177: 2021 | B1177: 27 | C1177: =C1176+7 -> 44386 | D1177: =+[1]fedcat!$CS31 -> 171.98 | E1177: =+[1]fedcat!$AB31 -> 155.8
A1178: 2021 | B1178: 28 | C1178: =C1177+7 -> 44393 | D1178: =+[1]fedcat!$CS32 -> 181.25 | E1178: =+[1]fedcat!$AB32 -> 157.65
A1179: 2021 | B1179: 29 | C1179: =C1178+7 -> 44400 | D1179: =+[1]fedcat!$CS33 -> 176.98 | E1179: =+[1]fedcat!$AB33 -> 156.99
...

Sheet Feed Cost
H1: Feedlot - Steer
B2: Corn | D2: Corn Silage | E2: Distillers Dried Grain | F2: Soymeal | G2: Concentrate | H2: Feed Cost
A3: Source | B3: Farm Market News | D3: OMAFRA 5 year Historicl % of Corn Price | E3: Farm Market News | F3: Farm Market News | G3: RMP produced % of Soymeal Price | H3: Based on RMP
A4: Assumptions | B4: Includes $15 per tonne for delivery to farm since most producers don’t truck the feed themselves | D4: Corn silage is worht 16.16% the value of a tonne of grain corn | H4: 1802.4lbs of silage, 3715.4lbs of corn, 964.9lbs of DDGS, 272.4lbs of concentrate to take 900lb steer to 1500lb at 3.25lbs per day of gain
A5: Units | B5: $/bu | C5: $/tonne | D5: $/tonne | E5: $/tonne | F5: $/tonne | G5: $/tonne | H5: $ per 1500lb Steer | I5: =1500-900 -> 600 | J5: =+I5/3.25 -> 184.61538 | K5: =+J5/7 -> 26.373626
A6: =A7-7 -> 36168 | B6: 2.7925 | C6: =B6*39.368+15 -> 124.93514 | D6: =C6*0.1616 -> 20.189519 | E6: 119.18002 | F6: 258.121 | G6: =F6*1.43 -> 369.11303 | H6: =($D6/2204.62)*1802.4+($C6/2204.62)*3715.4+($E6/2204.62)*964.9+(G6/2204.62)*272.4 -> 324.8255
A7: =A8-7 -> 36175 | B7: 2.73 | C7: =B7*39.368+15 -> 122.47464 | D7: =C7*0.1616 -> 19.791902 | E7: 120.97163 | F7: 248.708 | G7: =F7*1.43 -> 355.65244 | H7: =($D7/2204.62)*1802.4+($C7/2204.62)*3715.4+($E7/2204.62)*964.9+(G7/2204.62)*272.4 -> 319.47476
A8: =A9-7 -> 36182 | B8: 2.7625 | C8: =B8*39.368+15 -> 123.7541 | D8: =C8*0.1616 -> 19.998663 | E8: 120.0311 | F8: 244.497 | G8: =F8*1.43 -> 349.63071 | H8: =($D8/2204.62)*1802.4+($C8/2204.62)*3715.4+($E8/2204.62)*964.9+(G8/2204.62)*272.4 -> 320.64437
A9: =A10-7 -> 36189 | B9: 2.77 | C9: =B9*39.368+15 -> 124.04936 | D9: =C9*0.1616 -> 20.046377 | E9: 119.81681 | F9: 242.796 | G9: =F9*1.43 -> 347.19828 | H9: =($D9/2204.62)*1802.4+($C9/2204.62)*3715.4+($E9/2204.62)*964.9+(G9/2204.62)*272.4 -> 320.78664
A10: =A11-7 -> 36196 | B10: 2.81 | C10: =B10*39.368+15 -> 125.62408 | D10: =C10*0.1616 -> 20.300851 | E10: 118.69094 | F10: 248.465 | G10: =F10*1.43 -> 355.30495 | H10: =($D10/2204.62)*1802.4+($C10/2204.62)*3715.4+($E10/2204.62)*964.9+(AVERAGE(G1:G9)/2204.62)*272.4 -> 324.16899
A11: =A12-7 -> 36203 | B11: 2.775 | C11: =B11*39.368+15 -> 124.2462 | D11: =C11*0.1616 -> 20.078186 | E11: 119.67452 | F11: 240.926 | G11: =F11*1.43 -> 344.52418 | H11: =($D11/2204.62)*1802.4+($C11/2204.62)*3715.4+($E11/2204.62)*964.9+(AVERAGE(G2:G10)/2204.62)*272.4 -> 322.093
A12: =A13-7 -> 36210 | B12: 2.775 | C12: =B12*39.368+15 -> 124.2462 | D12: =C12*0.1616 -> 20.078186 | E12: 119.67452 | F12: 238.874 | G12: =F12*1.43 -> 341.58982 | H12: =($D12/2204.62)*1802.4+($C12/2204.62)*3715.4+($E12/2204.62)*964.9+(AVERAGE(G3:G11)/2204.62)*272.4 -> 321.86945
A13: =A14-7 -> 36217 | B13: 2.6775 | C13: =B13*39.368+15 -> 120.40782 | D13: =C13*0.1616 -> 19.457904 | E13: 122.53318 | F13: 229.021 | G13: =F13*1.43 -> 327.50003 | H13: =($D13/2204.62)*1802.4+($C13/2204.62)*3715.4+($E13/2204.62)*964.9+(AVERAGE(G4:G12)/2204.62)*272.4 -> 315.93327
A14: =A15-7 -> 36224 | B14: 2.76 | C14: =B14*39.368+15 -> 123.65568 | D14: =C14*0.1616 -> 19.982758 | E14: 120.10276 | F14: 232.176 | G14: =F14*1.43 -> 332.01168 | H14: =($D14/2204.62)*1802.4+($C14/2204.62)*3715.4+($E14/2204.62)*964.9+(AVERAGE(G5:G13)/2204.62)*272.4 -> 320.39597
A15: =A16-7 -> 36231 | B15: 2.8775 | C15: =B15*39.368+15 -> 128.28142 | D15: =C15*0.1616 -> 20.730277 | E15: 116.85372 | F15: 236.736 | G15: =F15*1.43 -> 338.53248 | H15: =($D15/2204.62)*1802.4+($C15/2204.62)*3715.4+($E15/2204.62)*964.9+(AVERAGE(G6:G14)/2204.62)*272.4 -> 327.15008
A16: =A17-7 -> 36238 | B16: 2.94 | C16: =B16*39.368+15 -> 130.74192 | D16: =C16*0.1616 -> 21.127894 | E16: 115.21917 | F16: 235.942 | G16: =F16*1.43 -> 337.39706 | H16: =($D16/2204.62)*1802.4+($C16/2204.62)*3715.4+($E16/2204.62)*964.9+($G16/2204.62)*272.4 -> 329.72639
A17: =A18-7 -> 36245 | B17: 2.9975 | C17: =B17*39.368+15 -> 133.00558 | D17: =C17*0.1616 -> 21.493702 | E17: 113.7688 | F17: 239.757 | G17: =F17*1.43 -> 342.85251 | H17: =($D17/2204.62)*1802.4+($C17/2204.62)*3715.4+($E17/2204.62)*964.9+($G17/2204.62)*272.4 -> 333.87964
A18: =A19-7 -> 36252 | B18: 2.92 | C18: =B18*39.368+15 -> 129.95456 | D18: =C18*0.1616 -> 21.000657 | E18: 115.73549 | F18: 237.794 | G18: =F18*1.43 -> 340.04542 | H18: =($D18/2204.62)*1802.4+($C18/2204.62)*3715.4+($E18/2204.62)*964.9+($G18/2204.62)*272.4 -> 328.84865
A19: =A20-7 -> 36259 | B19: 2.84 | C19: =B19*39.368+15 -> 126.80512 | D19: =C19*0.1616 -> 20.491707 | E19: 117.86489 | F19: 238.521 | G19: =F19*1.43 -> 341.08503 | H19: =($D19/2204.62)*1802.4+($C19/2204.62)*3715.4+($E19/2204.62)*964.9+($G19/2204.62)*272.4 -> 324.1853
A20: =A21-7 -> 36266 | B20: 2.91 | C20: =B20*39.368+15 -> 129.56088 | D20: =C20*0.1616 -> 20.937038 | E20: 115.99601 | F20: 235.81 | G20: =F20*1.43 -> 337.2083 | H20: =($D20/2204.62)*1802.4+($C20/2204.62)*3715.4+($E20/2204.62)*964.9+($G20/2204.62)*272.4 -> 327.89664
A21: =A22-7 -> 36273 | B21: 3.0025 | C21: =B21*39.368+15 -> 133.20242 | D21: =C21*0.1616 -> 21.525511 | E21: 113.64501 | F21: 221.47 | G21: =F21*1.43 -> 316.7021 | H21: =($D21/2204.62)*1802.4+($C21/2204.62)*3715.4+($E21/2204.62)*964.9+($G21/2204.62)*272.4 -> 330.95208
A22: =A23-7 -> 36280 | B22: 2.9125 | C22: =B22*39.368+15 -> 129.6593 | D22: =C22*0.1616 -> 20.952943 | E22: 115.93073 | F22: 227.874 | G22: =F22*1.43 -> 325.85982 | H22: =($D22/2204.62)*1802.4+($C22/2204.62)*3715.4+($E22/2204.62)*964.9+($G22/2204.62)*272.4 -> 326.64474
A23: =A24-7 -> 36287 | B23: 2.91 | C23: =B23*39.368+15 -> 129.56088 | D23: =C23*0.1616 -> 20.937038 | E23: 115.99601 | F23: 230.982 | G23: =F23*1.43 -> 330.30426 | H23: =($D23/2204.62)*1802.4+($C23/2204.62)*3715.4+($E23/2204.62)*964.9+($G23/2204.62)*272.4 -> 327.04359
A24: =A25-7 -> 36294 | B24: 2.9175 | C24: =B24*39.368+15 -> 129.85614 | D24: =C24*0.1616 -> 20.984752 | E24: 115.80047 | F24: 235.811 | G24: =F24*1.43 -> 337.20973 | H24: =($D24/2204.62)*1802.4+($C24/2204.62)*3715.4+($E24/2204.62)*964.9+($G24/2204.62)*272.4 -> 328.34785
A25: =A26-7 -> 36301 | B25: 2.885 | C25: =B25*39.368+15 -> 128.57668 | D25: =C25*0.1616 -> 20.777991 | E25: 116.65427 | F25: 231.248 | G25: =F25*1.43 -> 330.68464 | H25: =($D25/2204.62)*1802.4+($C25/2204.62)*3715.4+($E25/2204.62)*964.9+($G25/2204.62)*272.4 -> 325.59001
A26: =A27-7 -> 36308 | B26: 2.845 | C26: =B26*39.368+15 -> 127.00196 | D26: =C26*0.1616 -> 20.523517 | E26: 117.72871 | F26: 232.99 | G26: =F26*1.43 -> 333.1757 | H26: =($D26/2204.62)*1802.4+($C26/2204.62)*3715.4+($E26/2204.62)*964.9+($G26/2204.62)*272.4 -> 323.50617
A27: =A28-7 -> 36315 | B27: 2.8075 | C27: =B27*39.368+15 -> 125.52566 | D27: =C27*0.1616 -> 20.284947 | E27: 118.76048 | F27: 238.258 | G27: =F27*1.43 -> 340.70894 | H27: =($D27/2204.62)*1802.4+($C27/2204.62)*3715.4+($E27/2204.62)*964.9+($G27/2204.62)*272.4 -> 322.20552
... A32: =A33-7 -> 36350 | B32: 2.4525 | C32: =B32*39.368+15 -> 111.55002 | D32: =C32*0.1616 -> 18.026483 | E32: 129.88092 | F32: 228.404 | G32: =F32*1.43 -> 326.61772 | H32: =($D32/2204.62)*1802.4+($C32/2204.62)*3715.4+($E32/2204.62)*964.9+($G32/2204.62)*272.4 -> 299.93225
A33: =A34-7 -> 36357 | B33: 2.4525 | C33: =B33*39.368+15 -> 111.55002 | D33: =C33*0.1616 -> 18.026483 | E33: 129.88092 | F33: 237.333 | G33: =F33*1.43 -> 339.38619 | H33: =(AVERAGE(D6:D32)/2204.62)*1802.4+(AVERAGE(C6:C32)/2204.62)*3715.4+(AVERAGE(E6:E32)/2204.62)*964.9+(AVERAGE(G6:G32)/2204.62)*272.4 -> 322.84415
A34: =A35-7 -> 36364 | B34: 2.745 | C34: =B34*39.368+15 -> 123.06516 | D34: =C34*0.1616 -> 19.88733 | E34: 120.53511 | F34: 240.461 | G34: =F34*1.43 -> 343.85923 | H34: =(AVERAGE(D7:D33)/2204.62)*1802.4+(AVERAGE(C7:C33)/2204.62)*3715.4+(AVERAGE(E7:E33)/2204.62)*964.9+(AVERAGE(G7:G33)/2204.62)*272.4 -> 321.98061
A35: =A36-7 -> 36371 | B35: 2.6825 | C35: =B35*39.368+15 -> 120.60466 | D35: =C35*0.1616 -> 19.489713 | E35: 122.38215 | F35: 252.874 | G35: =F35*1.43 -> 361.60982 | H35: =(AVERAGE(D8:D34)/2204.62)*1802.4+(AVERAGE(C8:C34)/2204.62)*3715.4+(AVERAGE(E8:E34)/2204.62)*964.9+(AVERAGE(G8:G34)/2204.62)*272.4 -> 321.95932
A36: =A37-7 -> 36378 | B36: 2.885 | C36: =B36*39.368+15 -> 128.57668 | D36: =C36*0.1616 -> 20.777991 | E36: 116.65427 | F36: 251.221 | G36: =F36*1.43 -> 359.24603 | H36: =(AVERAGE(D9:D35)/2204.62)*1802.4+(AVERAGE(C9:C35)/2204.62)*3715.4+(AVERAGE(E9:E35)/2204.62)*964.9+(AVERAGE(G9:G35)/2204.62)*272.4 -> 321.84025
A37: =A38-7 -> 36385 | B37: 2.76 | C37: =B37*39.368+15 -> 123.65568 | D37: =C37*0.1616 -> 19.982758 | E37: 120.10276 | F37: 243.638 | G37: =F37*1.43 -> 348.40234 | H37: =(AVERAGE(D10:D36)/2204.62)*1802.4+(AVERAGE(C10:C36)/2204.62)*3715.4+(AVERAGE(E10:E36)/2204.62)*964.9+(AVERAGE(G10:G36)/2204.62)*272.4 -> 322.14886
A38: =A39-7 -> 36392 | B38: 2.7725 | C38: =B38*39.368+15 -> 124.14778 | D38: =C38*0.1616 -> 20.062281 | E38: 119.74561 | F38: 238.082 | G38: =F38*1.43 -> 340.45726 | H38: =(AVERAGE(D11:D37)/2204.62)*1802.4+(AVERAGE(C11:C37)/2204.62)*3715.4+(AVERAGE(E11:E37)/2204.62)*964.9+(AVERAGE(G11:G37)/2204.62)*272.4 -> 322.00766
A39: =A40-7 -> 36399 | B39: 2.8025 | C39: =B39*39.368+15 -> 125.32882 | D39: =C39*0.1616 -> 20.253137 | E39: 118.89989 | F39: 243.637 | G39: =F39*1.43 -> 348.40091 | H39: =(AVERAGE(D12:D38)/2204.62)*1802.4+(AVERAGE(C12:C38)/2204.62)*3715.4+(AVERAGE(E12:E38)/2204.62)*964.9+(AVERAGE(G12:G38)/2204.62)*272.4 -> 321.98358
A40: =A41-7 -> 36406 | B40: 2.925 | C40: =B40*39.368+15 -> 130.1514 | D40: =C40*0.1616 -> 21.032466 | E40: 115.60583 | F40: 254.859 | G40: =F40*1.43 -> 364.44837 | H40: =(AVERAGE(D13:D39)/2204.62)*1802.4+(AVERAGE(C13:C39)/2204.62)*3715.4+(AVERAGE(E13:E39)/2204.62)*964.9+(AVERAGE(G13:G39)/2204.62)*272.4 -> 322.07507
A41: =A42-7 -> 36413 | B41: 2.8525 | C41: =B41*39.368+15 -> 127.29722 | D41: =C41*0.1616 -> 20.571231 | E41: 117.52523 | F41: 250.67 | G41: =F41*1.43 -> 358.4581 | H41: =(AVERAGE(D14:D40)/2204.62)*1802.4+(AVERAGE(C14:C40)/2204.62)*3715.4+(AVERAGE(E14:E40)/2204.62)*964.9+(AVERAGE(G14:G40)/2204.62)*272.4 -> 322.78771
A42: =A43-7 -> 36420 | B42: 2.8275 | C42: =B42*39.368+15 -> 126.31302 | D42: =C42*0.1616 -> 20.412184 | E42: 118.2072 | F42: 245.488 | G42: =F42*1.43 -> 351.04784 | H42: =(AVERAGE(D15:D41)/2204.62)*1802.4+(AVERAGE(C15:C41)/2204.62)*3715.4+(AVERAGE(E15:E41)/2204.62)*964.9+(AVERAGE(G15:G41)/2204.62)*272.4 -> 323.11207
A43: =A44-7 -> 36427 | B43: 2.8125 | C43: =B43*39.368+15 -> 125.7225 | D43: =C43*0.1616 -> 20.316756 | E43: 118.62151 | F43: 250.405 | G43: =F43*1.43 -> 358.07915 | H43: =(AVERAGE(D16:D42)/2204.62)*1802.4+(AVERAGE(C16:C42)/2204.62)*3715.4+(AVERAGE(E16:E42)/2204.62)*964.9+(AVERAGE(G16:G42)/2204.62)*272.4 -> 323.05878
A44: =A45-7 -> 36434 | B44: 2.775 | C44: =B44*39.368+15 -> 124.2462 | D44: =C44*0.1616 -> 20.078186 | E44: 119.67452 | F44: 251.684 | G44: =F44*1.43 -> 359.90812 | H44: =(AVERAGE(D17:D43)/2204.62)*1802.4+(AVERAGE(C17:C43)/2204.62)*3715.4+(AVERAGE(E17:E43)/2204.62)*964.9+(AVERAGE(G17:G43)/2204.62)*272.4 -> 322.87072
...

Sheet Fed Steer Margin
B1: Ontario - 1500lb steers
B2: Ontario 900lb Stocker Steer Price | C2: Feed Cost | D2: Fed Steer Costs | E2: Fed Steer Revenue | F2: Fed Steer Margin
B3: BFO | C3: RMP
A4: Week Ending | B4: $ per 900lb steer | C4: $ per 1500lb steer | D4: $ per 1500lb steer | E4: $ per 1500lb steer | F4: $ per 1500lb steer
A5: =A6-7 -> 36350 | B5: ='[5]Fed Steer Margin'!B5 -> 824.04 | C5: ='[5]Fed Steer Margin'!C5 -> 299.93225 | D5: ='[5]Fed Steer Margin'!D5 -> 1123.9723 | E5: ='[5]Fed Steer Margin'!E5 -> 1335.45 | F5: ='[5]Fed Steer Margin'!F5 -> 211.47775
A6: =A7-7 -> 36357 | B6: ='[5]Fed Steer Margin'!B6 -> 885.6 | C6: ='[5]Fed Steer Margin'!C6 -> 322.84415 | D6: ='[5]Fed Steer Margin'!D6 -> 1208.4442 | E6: ='[5]Fed Steer Margin'!E6 -> 1313.7 | F6: ='[5]Fed Steer Margin'!F6 -> 105.25585
A7: =A8-7 -> 36364 | B7: ='[5]Fed Steer Margin'!B7 -> 916.92 | C7: ='[5]Fed Steer Margin'!C7 -> 321.98061 | D7: ='[5]Fed Steer Margin'!D7 -> 1238.9006 | E7: ='[5]Fed Steer Margin'!E7 -> 1356.15 | F7: ='[5]Fed Steer Margin'!F7 -> 117.24939
A8: =A9-7 -> 36371 | B8: ='[5]Fed Steer Margin'!B8 -> 892.62 | C8: ='[5]Fed Steer Margin'!C8 -> 321.95932 | D8: ='[5]Fed Steer Margin'!D8 -> 1214.5793 | E8: ='[5]Fed Steer Margin'!E8 -> 1362.9 | F8: ='[5]Fed Steer Margin'!F8 -> 148.32068
A9: =A10-7 -> 36378 | B9: ='[5]Fed Steer Margin'!B9 -> 917.73 | C9: ='[5]Fed Steer Margin'!C9 -> 321.84025 | D9: ='[5]Fed Steer Margin'!D9 -> 1239.5703 | E9: ='[5]Fed Steer Margin'!E9 -> 1358.1 | F9: ='[5]Fed Steer Margin'!F9 -> 118.52975
A10: =A11-7 -> 36385 | B10: ='[5]Fed Steer Margin'!B10 -> 932.13 | C10: ='[5]Fed Steer Margin'!C10 -> 322.14886 | D10: ='[5]Fed Steer Margin'!D10 -> 1254.2789 | E10: ='[5]Fed Steer Margin'!E10 -> 1355.85 | F10: ='[5]Fed Steer Margin'!F10 -> 101.57114
A11: =A12-7 -> 36392 | B11: ='[5]Fed Steer Margin'!B11 -> 902.88 | C11: ='[5]Fed Steer Margin'!C11 -> 322.00766 | D11: ='[5]Fed Steer Margin'!D11 -> 1224.8877 | E11: ='[5]Fed Steer Margin'!E11 -> 1349.85 | F11: ='[5]Fed Steer Margin'!F11 -> 124.96234
A12: =A13-7 -> 36399 | B12: ='[5]Fed Steer Margin'!B12 -> 911.43 | C12: ='[5]Fed Steer Margin'!C12 -> 321.98358 | D12: ='[5]Fed Steer Margin'!D12 -> 1233.4136 | E12: ='[5]Fed Steer Margin'!E12 -> 1348.8 | F12: ='[5]Fed Steer Margin'!F12 -> 115.38642
A13: =A14-7 -> 36406 | B13: ='[5]Fed Steer Margin'!B13 -> 923.22 | C13: ='[5]Fed Steer Margin'!C13 -> 322.07507 | D13: ='[5]Fed Steer Margin'!D13 -> 1245.2951 | E13: ='[5]Fed Steer Margin'!E13 -> 1347.3 | F13: ='[5]Fed Steer Margin'!F13 -> 102.00493
A14: =A15-7 -> 36413 | B14: ='[5]Fed Steer Margin'!B14 -> 932.22 | C14: ='[5]Fed Steer Margin'!C14 -> 322.78771 | D14: ='[5]Fed Steer Margin'!D14 -> 1255.0077 | E14: ='[5]Fed Steer Margin'!E14 -> 1348.8 | F14: ='[5]Fed Steer Margin'!F14 -> 93.792293
A15: =A16-7 -> 36420 | B15: ='[5]Fed Steer Margin'!B15 -> 908.91 | C15: ='[5]Fed Steer Margin'!C15 -> 323.11207 | D15: ='[5]Fed Steer Margin'!D15 -> 1232.0221 | E15: ='[5]Fed Steer Margin'!E15 -> 1349.55 | F15: ='[5]Fed Steer Margin'!F15 -> 117.52793
A16: =A17-7 -> 36427 | B16: ='[5]Fed Steer Margin'!B16 -> 919.71 | C16: ='[5]Fed Steer Margin'!C16 -> 323.05878 | D16: ='[5]Fed Steer Margin'!D16 -> 1242.7688 | E16: ='[5]Fed Steer Margin'!E16 -> 1346.7 | F16: ='[5]Fed Steer Margin'!F16 -> 103.93122
... A619: =A620-7 -> 40648 | B619: ='[5]Fed Steer Margin'!B619 -> 989.55 | C619: ='[5]Fed Steer Margin'!C619 -> 591.67473 | D619: ='[5]Fed Steer Margin'!D619 -> 1581.2247 | E619: ='[5]Fed Steer Margin'!E619 -> 1627.05 | F619: ='[5]Fed Steer Margin'!F619 -> 45.825267
A620: 40655 | B620: ='[5]Fed Steer Margin'!B620 -> 953.55 | C620: ='[5]Fed Steer Margin'!C620 -> 598.39156 | D620: ='[5]Fed Steer Margin'!D620 -> 1551.9416 | E620: ='[5]Fed Steer Margin'!E620 -> 1632.75 | F620: ='[5]Fed Steer Margin'!F620 -> 80.808441
A621: =A620+7 -> 40662 | B621: ='[5]Fed Steer Margin'!B621 -> 954.9 | C621: ='[5]Fed Steer Margin'!C621 -> 604.52511 | D621: ='[5]Fed Steer Margin'!D621 -> 1559.4251 | E621: ='[5]Fed Steer Margin'!E621 -> 1639.2 | F621: ='[5]Fed Steer Margin'!F621 -> 79.774892
A622: =A621+7 -> 40669 | B622: ='[5]Fed Steer Margin'!B622 -> 962.73 | C622: ='[5]Fed Steer Margin'!C622 -> 609.47932 | D622: ='[5]Fed Steer Margin'!D622 -> 1572.2093 | E622: ='[5]Fed Steer Margin'!E622 -> 1613.55 | F622: ='[5]Fed Steer Margin'!F622 -> 41.340681
A623: =A622+7 -> 40676 | B623: ='[5]Fed Steer Margin'!B623 -> 1031.4 | C623: ='[5]Fed Steer Margin'!C623 -> 613.75823 | D623: ='[5]Fed Steer Margin'!D623 -> 1645.1582 | E623: ='[5]Fed Steer Margin'!E623 -> 1601.4 | F623: ='[5]Fed Steer Margin'!F623 -> -43.758229
A624: =A623+7 -> 40683 | B624: ='[5]Fed Steer Margin'!B624 -> 992.07 | C624: ='[5]Fed Steer Margin'!C624 -> 617.97091 | D624: ='[5]Fed Steer Margin'!D624 -> 1610.0409 | E624: ='[5]Fed Steer Margin'!E624 -> 1581.6 | F624: ='[5]Fed Steer Margin'!F624 -> -28.440906
A625: =A624+7 -> 40690 | B625: ='[5]Fed Steer Margin'!B625 -> 974.07 | C625: ='[5]Fed Steer Margin'!C625 -> 624.5718 | D625: ='[5]Fed Steer Margin'!D625 -> 1598.6418 | E625: ='[5]Fed Steer Margin'!E625 -> 1584.75 | F625: ='[5]Fed Steer Margin'!F625 -> -13.891802
A626: =A625+7 -> 40697 | B626: ='[5]Fed Steer Margin'!B626 -> 1048.59 | C626: ='[5]Fed Steer Margin'!C626 -> 631.29421 | D626: ='[5]Fed Steer Margin'!D626 -> 1679.8842 | E626: ='[5]Fed Steer Margin'!E626 -> 1552.5 | F626: ='[5]Fed Steer Margin'!F626 -> -127.38421
A627: =A626+7 -> 40704 | B627: ='[5]Fed Steer Margin'!B627 -> 1039.68 | C627: ='[5]Fed Steer Margin'!C627 -> 638.29921 | D627: ='[5]Fed Steer Margin'!D627 -> 1677.9792 | E627: ='[5]Fed Steer Margin'!E627 -> 1545.6 | F627: ='[5]Fed Steer Margin'!F627 -> -132.37921
A628: =A627+7 -> 40711 | B628: ='[5]Fed Steer Margin'!B628 -> 1049.22 | C628: ='[5]Fed Steer Margin'!C628 -> 645.59003 | D628: ='[5]Fed Steer Margin'!D628 -> 1694.81 | E628: ='[5]Fed Steer Margin'!E628 -> 1602.6 | F628: ='[5]Fed Steer Margin'!F628 -> -92.21003
A629: =A628+7 -> 40718 | B629: ='[5]Fed Steer Margin'!B629 -> 1021.86 | C629: ='[5]Fed Steer Margin'!C629 -> 651.64378 | D629: ='[5]Fed Steer Margin'!D629 -> 1673.5038 | E629: ='[5]Fed Steer Margin'!E629 -> 1653.15 | F629: ='[5]Fed Steer Margin'!F629 -> -20.353783
A630: =A629+7 -> 40725 | B630: ='[5]Fed Steer Margin'!B630 -> 1021.86 | C630: ='[5]Fed Steer Margin'!C630 -> 656.34694 | D630: ='[5]Fed Steer Margin'!D630 -> 1678.2069 | E630: ='[5]Fed Steer Margin'!E630 -> 1639.65 | F630: ='[5]Fed Steer Margin'!F630 -> -38.556937
A631: =A630+7 -> 40732 | B631: ='[5]Fed Steer Margin'!B631 -> 1036.8 | C631: ='[5]Fed Steer Margin'!C631 -> 659.90708 | D631: ='[5]Fed Steer Margin'!D631 -> 1696.7071 | E631: ='[5]Fed Steer Margin'!E631 -> 1639.65 | F631: ='[5]Fed Steer Margin'!F631 -> -57.05708
A632: =A631+7 -> 40739 | B632: ='[5]Fed Steer Margin'!B632 -> 1055.34 | C632: ='[5]Fed Steer Margin'!C632 -> 663.04292 | D632: ='[5]Fed Steer Margin'!D632 -> 1718.3829 | E632: ='[5]Fed Steer Margin'!E632 -> 1614.9 | F632: ='[5]Fed Steer Margin'!F632 -> -103.48292
... A1073: =A1072+7 -> 43826 | B1073: ='[5]Fed Steer Margin'!B1073 -> 1470.33 | C1073: ='[5]Fed Steer Margin'!C1073 -> 592.10368 | D1073: ='[5]Fed Steer Margin'!D1073 -> 2062.4337 | E1073: ='[5]Fed Steer Margin'!E1073 -> 2068.95 | F1073: ='[5]Fed Steer Margin'!F1073 -> 6.516319
A1074: =A1073+7 -> 43833 | B1074: ='[5]Fed Steer Margin'!B1074 -> 1445.58 | C1074: ='[5]Fed Steer Margin'!C1074 -> 590.3984 | D1074: ='[5]Fed Steer Margin'!D1074 -> 2035.9784 | E1074: ='[5]Fed Steer Margin'!E1074 -> 2056.95 | F1074: ='[5]Fed Steer Margin'!F1074 -> 20.971604 | G1074: =+(F1074-F1022)/ABS(F1022) -> -0.78892859
A1075: =A1074+7 -> 43840 | B1075: ='[5]Fed Steer Margin'!B1075 -> 1544.67 | C1075: ='[5]Fed Steer Margin'!C1075 -> 588.70352 | D1075: ='[5]Fed Steer Margin'!D1075 -> 2133.3735 | E1075: ='[5]Fed Steer Margin'!E1075 -> 2095.65 | F1075: ='[5]Fed Steer Margin'!F1075 -> -37.723515 | G1075: =+(F1075-F1023)/ABS(F1023) -> -1.7465958
A1076: =A1075+7 -> 43847 | B1076: ='[5]Fed Steer Margin'!B1076 -> 1574.19 | C1076: ='[5]Fed Steer Margin'!C1076 -> 587.31679 | D1076: ='[5]Fed Steer Margin'!D1076 -> 2161.5068 | E1076: ='[5]Fed Steer Margin'!E1076 -> 2146.8 | F1076: ='[5]Fed Steer Margin'!F1076 -> -14.706794 | G1076: =+(F1076-F1024)/ABS(F1024) -> -17.478731
A1077: =A1076+7 -> 43854 | B1077: ='[5]Fed Steer Margin'!B1077 -> 1625.49 | C1077: ='[5]Fed Steer Margin'!C1077 -> 585.24295 | D1077: ='[5]Fed Steer Margin'!D1077 -> 2210.7329 | E1077: ='[5]Fed Steer Margin'!E1077 -> 2157.3 | F1077: ='[5]Fed Steer Margin'!F1077 -> -53.432945 | G1077: =+(F1077-F1025)/ABS(F1025) -> -13.945116
A1078: =A1077+7 -> 43861 | B1078: ='[5]Fed Steer Margin'!B1078 -> 1619.46 | C1078: ='[5]Fed Steer Margin'!C1078 -> 583.20257 | D1078: ='[5]Fed Steer Margin'!D1078 -> 2202.6626 | E1078: ='[5]Fed Steer Margin'!E1078 -> 2151.45 | F1078: ='[5]Fed Steer Margin'!F1078 -> -51.212566 | G1078: =+(F1078-F1026)/ABS(F1026) -> -0.20702459
A1079: =A1078+7 -> 43868 | B1079: ='[5]Fed Steer Margin'!B1079 -> 1645.2 | C1079: ='[5]Fed Steer Margin'!C1079 -> 581.28133 | D1079: ='[5]Fed Steer Margin'!D1079 -> 2226.4813 | E1079: ='[5]Fed Steer Margin'!E1079 -> 2082.75 | F1079: ='[5]Fed Steer Margin'!F1079 -> -143.73133 | G1079: =+(F1079-F1027)/ABS(F1027) -> -41.554488
A1080: =A1079+7 -> 43875 | B1080: ='[5]Fed Steer Margin'!B1080 -> 1669.59 | C1080: ='[5]Fed Steer Margin'!C1080 -> 579.88198 | D1080: ='[5]Fed Steer Margin'!D1080 -> 2249.472 | E1080: ='[5]Fed Steer Margin'!E1080 -> 2083.95 | F1080: ='[5]Fed Steer Margin'!F1080 -> -165.52198 | G1080: =+(F1080-F1028)/ABS(F1028) -> -9.6988799
A1081: =A1080+7 -> 43882 | B1081: ='[5]Fed Steer Margin'!B1081 -> 1656.72 | C1081: ='[5]Fed Steer Margin'!C1081 -> 578.48996 | D1081: ='[5]Fed Steer Margin'!D1081 -> 2235.21 | E1081: ='[5]Fed Steer Margin'!E1081 -> 2099.4 | F1081: ='[5]Fed Steer Margin'!F1081 -> -135.80996 | G1081: =+(F1081-F1029)/ABS(F1029) -> -0.90988664
A1082: =A1081+7 -> 43889 | B1082: ='[5]Fed Steer Margin'!B1082 -> 1684.08 | C1082: ='[5]Fed Steer Margin'!C1082 -> 577.90592 | D1082: ='[5]Fed Steer Margin'!D1082 -> 2261.9859 | E1082: ='[5]Fed Steer Margin'!E1082 -> 2157.6 | F1082: ='[5]Fed Steer Margin'!F1082 -> -104.38592 | G1082: =+(F1082-F1030)/ABS(F1030) -> 0.2082726
...

Sheet FED STEER MARGIN_graphs
B1: Fed-steer margins
AC2: Last year | AD2: ='[5]FED STEER MARGIN_graphs'!M2 -> This year | AE2: ='[5]FED STEER MARGIN_graphs'!N2 -> 5-Year Ave (2021-25) | AF2: ='[5]FED STEER MARGIN_graphs'!O2 -> 10-Year Ave (2016-25) | AI2: Fed-Steer Margin ($ per 1,500 lbs Steer)
A3: ='[5]FED STEER MARGIN_graphs'!A3 -> Week No. | B3: Week No. | C3: 1999 | D3: 2000 | E3: 2001 | F3: 2002 | G3: 2003 | H3: 2004 | I3: 2005 | J3: 2006 | K3: 2007 | L3: 2008 | M3: 2009 | N3: 2010 | O3: 2011 | P3: 2012 | Q3: 2013 | R3: 2014 | S3: 2015 | T3: 2016 | U3: 2017 | V3: 2018 | W3: 2019 | X3: 2020 | Y3: 2021 | Z3: 2022 | AA3: 2023 | AB3: 2024 | AC3: 2025 | AD3: ='[5]FED STEER MARGIN_graphs'!M3 -> 2026 ytd | AE3: ='[5]FED STEER MARGIN_graphs'!N3 -> Avg 2021-25 | AF3: ='[5]FED STEER MARGIN_graphs'!O3 -> Avg 2016-25 | AI3: Weekly Fed Steer Margin
A4: ='[5]FED STEER MARGIN_graphs'!A4 -> 46024 | B4: 1 | D4: 309.72469 | E4: 296.88713 | F4: 28.041447 | G4: 314.67288 | H4: =+'Fed Steer Margin'!F239 -> 9.8879401 | I4: =+'Fed Steer Margin'!F292 -> 247.08351 | J4: =+'Fed Steer Margin'!F344 -> 325.30924 | K4: =+'Fed Steer Margin'!F396 -> 22.873419 | L4: =+'Fed Steer Margin'!F448 -> -184.88121 | M4: =+'Fed Steer Margin'!F500 -> 96.91539 | N4: =+'Fed Steer Margin'!F552 -> -96.425797 | O4: =+'Fed Steer Margin'!F605 -> 55.617415 | P4: =+'Fed Steer Margin'!$F657 -> 44.81085 | Q4: =+'Fed Steer Margin'!$F709 -> -192.12541 | R4: =+'Fed Steer Margin'!$F761 -> 196.33295 | S4: =+'Fed Steer Margin'!$F813 -> 175.85253 | T4: =+'Fed Steer Margin'!$F865 -> -82.958031 | U4: =+'Fed Steer Margin'!$F918 -> 88.873176 | V4: =+'Fed Steer Margin'!$F970 -> 201.03332 | W4: =+'Fed Steer Margin'!F1022 -> 99.357863 | X4: =+'Fed Steer Margin'!F1074 -> 20.971604 | Y4: =+'Fed Steer Margin'!F1127 -> -161.66969 | Z4: =+'Fed Steer Margin'!F1179 -> 152.92234 | AA4: 163.93411 | AB4: -18.922336 | AC4: 375.17043 | AD4: ='[5]FED STEER MARGIN_graphs'!M4 | AE4: ='[5]FED STEER MARGIN_graphs'!N4 -> 102.28697 | AF4: ='[5]FED STEER MARGIN_graphs'!O4 -> 83.871279
A5: ='[5]FED STEER MARGIN_graphs'!A5 -> 46031 | B5: 2 | D5: 304.80967 | E5: 260.30392 | F5: 63.079106 | G5: 374.44331 | H5: =+'Fed Steer Margin'!F240 -> 119.13207 | I5: =+'Fed Steer Margin'!F293 -> 283.79875 | J5: =+'Fed Steer Margin'!F345 -> 297.66883 | K5: =+'Fed Steer Margin'!F397 -> 71.226461 | L5: =+'Fed Steer Margin'!F449 -> -169.26158 | M5: =+'Fed Steer Margin'!F501 -> 21.473272 | N5: =+'Fed Steer Margin'!F553 -> -121.27522 | O5: =+'Fed Steer Margin'!F606 -> 72.147894 | P5: =+'Fed Steer Margin'!$F658 -> 73.717807 | Q5: =+'Fed Steer Margin'!$F710 -> -194.91853 | R5: =+'Fed Steer Margin'!$F762 -> 274.79032 | S5: =+'Fed Steer Margin'!$F814 -> 451.51507 | T5: =+'Fed Steer Margin'!$F866 -> -60.222616 | U5: =+'Fed Steer Margin'!$F919 -> 123.81304 | V5: =+'Fed Steer Margin'!$F971 -> 154.62149 | W5: =+'Fed Steer Margin'!F1023 -> 50.527363 | X5: =+'Fed Steer Margin'!F1075 -> -37.723515 | Y5: =+'Fed Steer Margin'!F1128 -> -209.95352 | Z5: =+'Fed Steer Margin'!F1180 -> 228.52482 | AA5: 111.69075 | AB5: -12.920243 | AC5: 473.25976 | AD5: ='[5]FED STEER MARGIN_graphs'!M5 -> 148.55951 | AE5: ='[5]FED STEER MARGIN_graphs'!N5 -> 118.12031 | AF5: ='[5]FED STEER MARGIN_graphs'!O5 -> 82.161731 | AH5: 1
A6: ='[5]FED STEER MARGIN_graphs'!A6 -> 46038 | B6: 3 | D6: 316.97904 | E6: 272.37689 | F6: 101.18326 | G6: 434.44237 | H6: =+'Fed Steer Margin'!F241 -> 121.45628 | I6: =+'Fed Steer Margin'!F294 -> 317.17511 | J6: =+'Fed Steer Margin'!F346 -> 296.23102 | K6: =+'Fed Steer Margin'!F398 -> 60.917646 | L6: =+'Fed Steer Margin'!F450 -> -202.38873 | M6: =+'Fed Steer Margin'!F502 -> -10.792163 | N6: =+'Fed Steer Margin'!F554 -> -151.63083 | O6: =+'Fed Steer Margin'!F607 -> 79.504529 | P6: =+'Fed Steer Margin'!$F659 -> 108.94814 | Q6: =+'Fed Steer Margin'!$F711 -> -201.77539 | R6: =+'Fed Steer Margin'!$F763 -> 239.54507 | S6: =+'Fed Steer Margin'!$F815 -> 516.00806 | T6: =+'Fed Steer Margin'!$F867 -> -134.67107 | U6: =+'Fed Steer Margin'!$F920 -> 78.37233 | V6: =+'Fed Steer Margin'!$F972 -> -71.087481 | W6: =+'Fed Steer Margin'!F1024 -> 0.89247124 | X6: =+'Fed Steer Margin'!F1076 -> -14.706794 | Y6: =+'Fed Steer Margin'!F1129 -> -221.51277 | Z6: =+'Fed Steer Margin'!F1181 -> 153.54792 | AA6: 171.00441 | AB6: -87.093397 | AC6: 467.67641 | AD6: ='[5]FED STEER MARGIN_graphs'!M6 -> 97.292248 | AE6: ='[5]FED STEER MARGIN_graphs'!N6 -> 96.724514 | AF6: ='[5]FED STEER MARGIN_graphs'!O6 -> 34.242202 | AH6: 2
A7: ='[5]FED STEER MARGIN_graphs'!A7 -> 46045 | B7: 4 | D7: 321.19154 | E7: 310.31189 | F7: 63.433252 | G7: 346.42006 | H7: =+'Fed Steer Margin'!F242 -> 237.92038 | I7: =+'Fed Steer Margin'!F295 -> 325.89464 | J7: =+'Fed Steer Margin'!F347 -> 262.89962 | K7: =+'Fed Steer Margin'!F399 -> 40.781765 | L7: =+'Fed Steer Margin'!F451 -> -175.88824 | M7: =+'Fed Steer Margin'!F503 -> 4.0200255 | N7: =+'Fed Steer Margin'!F555 -> -72.377671 | O7: =+'Fed Steer Margin'!F608 -> 117.61546 | P7: =+'Fed Steer Margin'!$F660 -> 87.928195 | Q7: =+'Fed Steer Margin'!$F712 -> -181.56148 | R7: =+'Fed Steer Margin'!$F764 -> 299.73706 | S7: =+'Fed Steer Margin'!$F816 -> 409.62308 | T7: =+'Fed Steer Margin'!$F868 -> -108.02397 | U7: =+'Fed Steer Margin'!$F921 -> 215.38981 | V7: =+'Fed Steer Margin'!$F973 -> 29.076472 | W7: =+'Fed Steer Margin'!F1025 -> -3.575278 | X7: =+'Fed Steer Margin'!F1077 -> -53.432945 | Y7: =+'Fed Steer Margin'!F1130 -> -215.88885 | Z7: =+'Fed Steer Margin'!F1182 -> 151.10963 | AA7: 127.07551 | AB7: -0.66063005 | AC7: 497.65085 | AD7: ='[5]FED STEER MARGIN_graphs'!M7 -> 117.03142 | AE7: ='[5]FED STEER MARGIN_graphs'!N7 -> 111.8573 | AF7: ='[5]FED STEER MARGIN_graphs'!O7 -> 63.87206 | AH7: 3
A8: ='[5]FED STEER MARGIN_graphs'!A8 -> 46052 | B8: 5 | D8: 274.1102 | E8: 280.19104 | F8: 57.404373 | G8: 254.99888 | H8: =+'Fed Steer Margin'!F243 -> 103.26627 | I8: =+'Fed Steer Margin'!F296 -> 346.10547 | J8: =+'Fed Steer Margin'!F348 -> 218.45629 | K8: =+'Fed Steer Margin'!F400 -> 39.010863 | L8: =+'Fed Steer Margin'!F452 -> -167.567 | M8: =+'Fed Steer Margin'!F504 -> 35.207128 | N8: =+'Fed Steer Margin'!F556 -> -94.219598 | O8: =+'Fed Steer Margin'!F609 -> 33.039631 | P8: =+'Fed Steer Margin'!$F661 -> 41.933145 | Q8: =+'Fed Steer Margin'!$F713 -> -100.55679 | R8: =+'Fed Steer Margin'!$F765 -> 408.7663 | S8: =+'Fed Steer Margin'!$F817 -> 411.16536 | T8: =+'Fed Steer Margin'!$F869 -> -116.88525 | U8: =+'Fed Steer Margin'!$F922 -> 162.17586 | V8: =+'Fed Steer Margin'!$F974 -> 141.42396 | W8: =+'Fed Steer Margin'!F1026 -> -42.428768 | X8: =+'Fed Steer Margin'!F1078 -> -51.212566 | Y8: =+'Fed Steer Margin'!F1131 -> -216.87175 | Z8: =+'Fed Steer Margin'!F1183 -> 157.23661 | AA8: 140.33095 | AB8: -32.490874 | AC8: 490.83333 | AD8: ='[5]FED STEER MARGIN_graphs'!M8 -> 214.51122 | AE8: ='[5]FED STEER MARGIN_graphs'!N8 -> 107.80765 | AF8: ='[5]FED STEER MARGIN_graphs'!O8 -> 63.211151 | AH8: 4
A9: ='[5]FED STEER MARGIN_graphs'!A9 -> 46059 | B9: 6 | D9: 267.84874 | E9: 257.40255 | F9: 132.52363 | G9: 291.70098 | H9: =+'Fed Steer Margin'!F244 -> 63.029202 | I9: =+'Fed Steer Margin'!F297 -> 432.21829 | J9: =+'Fed Steer Margin'!F349 -> 204.36064 | K9: =+'Fed Steer Margin'!F401 -> 36.750254 | L9: =+'Fed Steer Margin'!F453 -> -159.36129 | M9: =+'Fed Steer Margin'!F505 -> -18.510144 | N9: =+'Fed Steer Margin'!F557 -> -71.185177 | O9: =+'Fed Steer Margin'!F610 -> 116.98305 | P9: =+'Fed Steer Margin'!$F662 -> 96.89485 | Q9: =+'Fed Steer Margin'!$F714 -> -166.16117 | R9: =+'Fed Steer Margin'!$F766 -> 365.72483 | S9: =+'Fed Steer Margin'!$F818 -> 418.68078 | T9: =+'Fed Steer Margin'!$F870 -> -138.07663 | U9: =+'Fed Steer Margin'!$F923 -> 114.28977 | V9: =+'Fed Steer Margin'!$F975 -> 92.020639 | W9: =+'Fed Steer Margin'!F1027 -> 3.5441535 | X9: =+'Fed Steer Margin'!F1079 -> -143.73133 | Y9: =+'Fed Steer Margin'!F1132 -> -276.15108 | Z9: =+'Fed Steer Margin'!F1184 -> 85.322042 | AA9: 155.93962 | AB9: 9.0948003 | AC9: 527.91568 | AD9: ='[5]FED STEER MARGIN_graphs'!M9 -> 229.56685 | AE9: ='[5]FED STEER MARGIN_graphs'!N9 -> 100.42421 | AF9: ='[5]FED STEER MARGIN_graphs'!O9 -> 43.016766 | AH9: 5
A10: ='[5]FED STEER MARGIN_graphs'!A10 -> 46066 | B10: 7 | D10: 267.89311 | E10: 304.40213 | F10: 211.28228 | G10: 293.88632 | H10: =+'Fed Steer Margin'!F245 -> -43.924386 | I10: =+'Fed Steer Margin'!F298 -> 441.47747 | J10: =+'Fed Steer Margin'!F350 -> 142.98822 | K10: =+'Fed Steer Margin'!F402 -> 63.512796 | L10: =+'Fed Steer Margin'!F454 -> -119.3229 | M10: =+'Fed Steer Margin'!F506 -> -39.993187 | N10: =+'Fed Steer Margin'!F558 -> -24.852815 | O10: =+'Fed Steer Margin'!F611 -> 64.189215 | P10: =+'Fed Steer Margin'!$F663 -> 45.087027 | Q10: =+'Fed Steer Margin'!$F715 -> -236.30802 | R10: =+'Fed Steer Margin'!$F767 -> 309.71744 | S10: =+'Fed Steer Margin'!$F819 -> 370.03342 | T10: =+'Fed Steer Margin'!$F871 -> -217.70911 | U10: =+'Fed Steer Margin'!$F924 -> 145.10976 | V10: =+'Fed Steer Margin'!$F976 -> 137.43026 | W10: =+'Fed Steer Margin'!F1028 -> -15.470963 | X10: =+'Fed Steer Margin'!F1080 -> -165.52198 | Y10: =+'Fed Steer Margin'!F1133 -> -365.19405 | Z10: =+'Fed Steer Margin'!F1185 -> 27.631441 | AA10: 142.82916 | AB10: -31.841686 | AC10: 394.6648 | AD10: ='[5]FED STEER MARGIN_graphs'!M10 -> 167.19901 | AE10: ='[5]FED STEER MARGIN_graphs'!N10 -> 33.617932 | AF10: ='[5]FED STEER MARGIN_graphs'!O10 -> 5.1927626 | AH10: 6
A11: ='[5]FED STEER MARGIN_graphs'!A11 -> 46073 | B11: 8 | D11: 255.01847 | E11: 289.14141 | F11: 157.22006 | G11: 191.51456 | H11: =+'Fed Steer Margin'!F246 -> -67.826954 | I11: =+'Fed Steer Margin'!F299 -> 389.32961 | J11: =+'Fed Steer Margin'!F351 -> 131.2874 | K11: =+'Fed Steer Margin'!F403 -> 104.66797 | L11: =+'Fed Steer Margin'!F455 -> -131.31799 | M11: =+'Fed Steer Margin'!F507 -> -52.550209 | N11: =+'Fed Steer Margin'!F559 -> -6.4521953 | O11: =+'Fed Steer Margin'!F612 -> 52.118235 | P11: =+'Fed Steer Margin'!$F664 -> 75.7574 | Q11: =+'Fed Steer Margin'!$F716 -> -190.24061 | R11: =+'Fed Steer Margin'!$F768 -> 317.57828 | S11: =+'Fed Steer Margin'!$F820 -> 416.35641 | T11: =+'Fed Steer Margin'!$F872 -> -213.94421 | U11: =+'Fed Steer Margin'!$F925 -> 153.65994 | V11: =+'Fed Steer Margin'!$F977 -> 194.15204 | W11: =+'Fed Steer Margin'!F1029 -> -71.108914 | X11: =+'Fed Steer Margin'!F1081 -> -135.80996 | Y11: =+'Fed Steer Margin'!F1134 -> -292.40558 | Z11: =+'Fed Steer Margin'!F1186 -> -35.251176 | AA11: 56.370607 | AB11: 186.2548 | AC11: 570.3878 | AD11: ='[5]FED STEER MARGIN_graphs'!M11 -> -88.294823 | AE11: ='[5]FED STEER MARGIN_graphs'!N11 -> 97.071289 | AF11: ='[5]FED STEER MARGIN_graphs'!O11 -> 41.230533 | AH11: 7
